<?xml version="1.0"?>
<robot name="slab_srb_robot" xmlns:xacro="http://ros.org/wiki/xacro">
    <material name="red">
        <color rgba="1.0 0.0 0.0 2.5"/>
    </material>


    <xacro:macro name="wheel_macro" params="parent prefix xyz">

        <joint name="${prefix}_joint" type="continuous">
            <origin xyz="${xyz}" rpy="${radians(-90)} 0 0"/>
            <parent link="${parent}"/>
            <child  link="${prefix}_link"/>
            <axis xyz="0 0 1" />
            <limit velocity="100.0" effort="100.0" />
            <dynamics damping="0.01"/>
        </joint>
        <link name="${prefix}_link">
            <inertial>
                <origin xyz="0 0 0" rpy="0 0 0"/>
                <mass value="0.001"/>
                <inertia ixx="0.0001" ixy="0.0" ixz="0.0" iyy="0.0001" iyz="0.0" izz="0.0001"/>
            </inertial>
            <visual>
                <geometry>
                    <cylinder radius="0.1225" length="0.06" />
                </geometry>
                <material name="red"/>
            </visual>
            <collision>
                <geometry>
                    <cylinder radius="0.1225" length="0.06" />
                </geometry>
            </collision>
        </link>

        <transmission name="${prefix}_trans">
            <type>transmission_interface/SimpleTransmission</type>
            <joint name="${prefix}_joint">
                <hardwareInterface>hardware_interface/VelocityJointInterface</hardwareInterface>
            </joint>
            <actuator name="${prefix}_motor">
                <hardwareInterface>hardware_interface/VelocityJointInterface</hardwareInterface>
                <mechanismReduction>1</mechanismReduction>
            </actuator>
        </transmission>

        <gazebo reference="${prefix}_link">
            <material>Gazebo/Red</material>
            <mu1 value="10.0" />
            <mu2 value="10.0" />
            <kp value="50000" />
            <kd value="100" />
        </gazebo>


    </xacro:macro> 


</robot>

